2025-07-29 20:13:59,822 [INFO] [31m[1mWARNING: This is a development server. Do not use it in a production deployment. Use a production WSGI server instead.[0m
 * Running on http://127.0.0.1:5000
2025-07-29 20:13:59,822 [INFO] [33mPress CTRL+C to quit[0m
2025-07-29 20:14:04,133 [INFO] 127.0.0.1 - - [29/Jul/2025 20:14:04] "GET / HTTP/1.1" 200 -
2025-07-29 20:14:04,428 [INFO] 127.0.0.1 - - [29/Jul/2025 20:14:04] "[36mGET /static/img/eye.png HTTP/1.1[0m" 304 -
2025-07-29 20:14:04,432 [INFO] 127.0.0.1 - - [29/Jul/2025 20:14:04] "[36mGET /static/img/bookmark.png HTTP/1.1[0m" 304 -
2025-07-29 20:14:04,432 [INFO] 127.0.0.1 - - [29/Jul/2025 20:14:04] "[36mGET /static/css/styles.min.css HTTP/1.1[0m" 304 -
2025-07-29 20:14:04,462 [ERROR] Exception on /favicon.ico [GET]
Traceback (most recent call last):
  File "D:\Projects\Python\curse_project\.venv\Lib\site-packages\flask\app.py", line 917, in full_dispatch_request
    rv = self.dispatch_request()
         ^^^^^^^^^^^^^^^^^^^^^^^
  File "D:\Projects\Python\curse_project\.venv\Lib\site-packages\flask\app.py", line 891, in dispatch_request
    self.raise_routing_exception(req)
  File "D:\Projects\Python\curse_project\.venv\Lib\site-packages\flask\app.py", line 500, in raise_routing_exception
    raise request.routing_exception  # type: ignore[misc]
    ^^^^^^^^^^^^^^^^^^^^^^^^^^^^^^^
  File "D:\Projects\Python\curse_project\.venv\Lib\site-packages\flask\ctx.py", line 362, in match_request
    result = self.url_adapter.match(return_rule=True)  # type: ignore
             ^^^^^^^^^^^^^^^^^^^^^^^^^^^^^^^^^^^^^^^^
  File "D:\Projects\Python\curse_project\.venv\Lib\site-packages\werkzeug\routing\map.py", line 629, in match
    raise NotFound() from None
werkzeug.exceptions.NotFound: 404 Not Found: The requested URL was not found on the server. If you entered the URL manually please check your spelling and try again.

During handling of the above exception, another exception occurred:

Traceback (most recent call last):
  File "D:\Projects\Python\curse_project\.venv\Lib\site-packages\flask\app.py", line 1511, in wsgi_app
    response = self.full_dispatch_request()
               ^^^^^^^^^^^^^^^^^^^^^^^^^^^^
  File "D:\Projects\Python\curse_project\.venv\Lib\site-packages\flask\app.py", line 919, in full_dispatch_request
    rv = self.handle_user_exception(e)
         ^^^^^^^^^^^^^^^^^^^^^^^^^^^^^
  File "D:\Projects\Python\curse_project\.venv\Lib\site-packages\flask\app.py", line 802, in handle_user_exception
    return self.handle_http_exception(e)
           ^^^^^^^^^^^^^^^^^^^^^^^^^^^^^
  File "D:\Projects\Python\curse_project\.venv\Lib\site-packages\flask\app.py", line 777, in handle_http_exception
    return self.ensure_sync(handler)(e)  # type: ignore[no-any-return]
           ^^^^^^^^^^^^^^^^^^^^^^^^^^^^
  File "D:\Projects\Python\curse_project\app.py", line 19, in not_found_error
    logging.ERROR("Запрошена несуществующая страница - 404")
TypeError: 'int' object is not callable
2025-07-29 20:14:04,480 [INFO] 127.0.0.1 - - [29/Jul/2025 20:14:04] "[35m[1mGET /favicon.ico HTTP/1.1[0m" 500 -
2025-07-29 20:14:04,514 [ERROR] Error on request:
Traceback (most recent call last):
  File "D:\Projects\Python\curse_project\.venv\Lib\site-packages\flask\app.py", line 917, in full_dispatch_request
    rv = self.dispatch_request()
         ^^^^^^^^^^^^^^^^^^^^^^^
  File "D:\Projects\Python\curse_project\.venv\Lib\site-packages\flask\app.py", line 891, in dispatch_request
    self.raise_routing_exception(req)
  File "D:\Projects\Python\curse_project\.venv\Lib\site-packages\flask\app.py", line 500, in raise_routing_exception
    raise request.routing_exception  # type: ignore[misc]
  File "D:\Projects\Python\curse_project\.venv\Lib\site-packages\flask\ctx.py", line 362, in match_request
    result = self.url_adapter.match(return_rule=True)  # type: ignore
             ^^^^^^^^^^^^^^^^^^^^^^^^^^^^^^^^^^^^^^^^^^^^^^^^^^^^^^^^
  File "D:\Projects\Python\curse_project\.venv\Lib\site-packages\werkzeug\routing\map.py", line 629, in match
    raise NotFound() from None
werkzeug.exceptions.NotFound: 404 Not Found: The requested URL was not found on the server. If you entered the URL manually please check your spelling and try again.

During handling of the above exception, another exception occurred:

Traceback (most recent call last):
  File "D:\Projects\Python\curse_project\.venv\Lib\site-packages\flask\app.py", line 1511, in wsgi_app
    response = self.full_dispatch_request()
               ^^^^^^^^^^^^^^^^^^^^^^^^^^^^
  File "D:\Projects\Python\curse_project\.venv\Lib\site-packages\flask\app.py", line 919, in full_dispatch_request
    rv = self.handle_user_exception(e)
         ^^^^^^^^^^^^^^^^^^^^^^^^^^^^^
  File "D:\Projects\Python\curse_project\.venv\Lib\site-packages\flask\app.py", line 802, in handle_user_exception
    return self.handle_http_exception(e)
           ^^^^^^^^^^^^^^^^^^^^^^^^^^^^^
  File "D:\Projects\Python\curse_project\.venv\Lib\site-packages\flask\app.py", line 777, in handle_http_exception
    return self.ensure_sync(handler)(e)  # type: ignore[no-any-return]
           ^^^^^^^^^^^^^^^^^^^^^^^^^^^^^^^^^^^^^^^^^^^^^^^^^^^^^^^^^^^
  File "D:\Projects\Python\curse_project\app.py", line 19, in not_found_error
    logging.ERROR("Запрошена несуществующая страница - 404")
TypeError: 'int' object is not callable

During handling of the above exception, another exception occurred:

Traceback (most recent call last):
  File "D:\Projects\Python\curse_project\.venv\Lib\site-packages\werkzeug\serving.py", line 370, in run_wsgi
    execute(self.server.app)
  File "D:\Projects\Python\curse_project\.venv\Lib\site-packages\werkzeug\serving.py", line 331, in execute
    application_iter = app(environ, start_response)
                       ^^^^^^^^^^^^^^^^^^^^^^^^^^^^
  File "D:\Projects\Python\curse_project\.venv\Lib\site-packages\flask\app.py", line 1536, in __call__
    return self.wsgi_app(environ, start_response)
           ^^^^^^^^^^^^^^^^^^^^^^^^^^^^^^^^^^^^^^
  File "D:\Projects\Python\curse_project\.venv\Lib\site-packages\flask\app.py", line 1514, in wsgi_app
    response = self.handle_exception(e)
               ^^^^^^^^^^^^^^^^^^^^^^^^
  File "D:\Projects\Python\curse_project\.venv\Lib\site-packages\flask\app.py", line 860, in handle_exception
    server_error = self.ensure_sync(handler)(server_error)
                   ^^^^^^^^^^^^^^^^^^^^^^^^^^^^^^^^^^^^^^^
  File "D:\Projects\Python\curse_project\app.py", line 24, in server_international_error
    logging.ERROR("Ошибка на стороне сервера - 500")
TypeError: 'int' object is not callable
2025-07-29 20:14:07,171 [INFO] 127.0.0.1 - - [29/Jul/2025 20:14:07] "GET /posts/1 HTTP/1.1" 200 -
2025-07-29 20:14:07,256 [ERROR] Exception on /posts/img/bookmark.png [GET]
Traceback (most recent call last):
  File "D:\Projects\Python\curse_project\.venv\Lib\site-packages\flask\app.py", line 917, in full_dispatch_request
    rv = self.dispatch_request()
         ^^^^^^^^^^^^^^^^^^^^^^^
  File "D:\Projects\Python\curse_project\.venv\Lib\site-packages\flask\app.py", line 891, in dispatch_request
    self.raise_routing_exception(req)
  File "D:\Projects\Python\curse_project\.venv\Lib\site-packages\flask\app.py", line 500, in raise_routing_exception
    raise request.routing_exception  # type: ignore[misc]
    ^^^^^^^^^^^^^^^^^^^^^^^^^^^^^^^
  File "D:\Projects\Python\curse_project\.venv\Lib\site-packages\flask\ctx.py", line 362, in match_request
    result = self.url_adapter.match(return_rule=True)  # type: ignore
             ^^^^^^^^^^^^^^^^^^^^^^^^^^^^^^^^^^^^^^^^
  File "D:\Projects\Python\curse_project\.venv\Lib\site-packages\werkzeug\routing\map.py", line 629, in match
    raise NotFound() from None
werkzeug.exceptions.NotFound: 404 Not Found: The requested URL was not found on the server. If you entered the URL manually please check your spelling and try again.

During handling of the above exception, another exception occurred:

Traceback (most recent call last):
  File "D:\Projects\Python\curse_project\.venv\Lib\site-packages\flask\app.py", line 1511, in wsgi_app
    response = self.full_dispatch_request()
               ^^^^^^^^^^^^^^^^^^^^^^^^^^^^
  File "D:\Projects\Python\curse_project\.venv\Lib\site-packages\flask\app.py", line 919, in full_dispatch_request
    rv = self.handle_user_exception(e)
         ^^^^^^^^^^^^^^^^^^^^^^^^^^^^^
  File "D:\Projects\Python\curse_project\.venv\Lib\site-packages\flask\app.py", line 802, in handle_user_exception
    return self.handle_http_exception(e)
           ^^^^^^^^^^^^^^^^^^^^^^^^^^^^^
  File "D:\Projects\Python\curse_project\.venv\Lib\site-packages\flask\app.py", line 777, in handle_http_exception
    return self.ensure_sync(handler)(e)  # type: ignore[no-any-return]
           ^^^^^^^^^^^^^^^^^^^^^^^^^^^^
  File "D:\Projects\Python\curse_project\app.py", line 19, in not_found_error
    logging.ERROR("Запрошена несуществующая страница - 404")
TypeError: 'int' object is not callable
2025-07-29 20:14:07,258 [INFO] 127.0.0.1 - - [29/Jul/2025 20:14:07] "[36mGET /static/css/styles.min.css HTTP/1.1[0m" 304 -
2025-07-29 20:14:07,261 [INFO] 127.0.0.1 - - [29/Jul/2025 20:14:07] "[35m[1mGET /posts/img/bookmark.png HTTP/1.1[0m" 500 -
2025-07-29 20:14:07,269 [ERROR] Error on request:
Traceback (most recent call last):
  File "D:\Projects\Python\curse_project\.venv\Lib\site-packages\flask\app.py", line 917, in full_dispatch_request
    rv = self.dispatch_request()
         ^^^^^^^^^^^^^^^^^^^^^^^
  File "D:\Projects\Python\curse_project\.venv\Lib\site-packages\flask\app.py", line 891, in dispatch_request
    self.raise_routing_exception(req)
  File "D:\Projects\Python\curse_project\.venv\Lib\site-packages\flask\app.py", line 500, in raise_routing_exception
    raise request.routing_exception  # type: ignore[misc]
  File "D:\Projects\Python\curse_project\.venv\Lib\site-packages\flask\ctx.py", line 362, in match_request
    result = self.url_adapter.match(return_rule=True)  # type: ignore
             ^^^^^^^^^^^^^^^^^^^^^^^^^^^^^^^^^^^^^^^^^^^^^^^^^^^^^^^^
  File "D:\Projects\Python\curse_project\.venv\Lib\site-packages\werkzeug\routing\map.py", line 629, in match
    raise NotFound() from None
werkzeug.exceptions.NotFound: 404 Not Found: The requested URL was not found on the server. If you entered the URL manually please check your spelling and try again.

During handling of the above exception, another exception occurred:

Traceback (most recent call last):
  File "D:\Projects\Python\curse_project\.venv\Lib\site-packages\flask\app.py", line 1511, in wsgi_app
    response = self.full_dispatch_request()
               ^^^^^^^^^^^^^^^^^^^^^^^^^^^^
  File "D:\Projects\Python\curse_project\.venv\Lib\site-packages\flask\app.py", line 919, in full_dispatch_request
    rv = self.handle_user_exception(e)
         ^^^^^^^^^^^^^^^^^^^^^^^^^^^^^
  File "D:\Projects\Python\curse_project\.venv\Lib\site-packages\flask\app.py", line 802, in handle_user_exception
    return self.handle_http_exception(e)
           ^^^^^^^^^^^^^^^^^^^^^^^^^^^^^
  File "D:\Projects\Python\curse_project\.venv\Lib\site-packages\flask\app.py", line 777, in handle_http_exception
    return self.ensure_sync(handler)(e)  # type: ignore[no-any-return]
           ^^^^^^^^^^^^^^^^^^^^^^^^^^^^^^^^^^^^^^^^^^^^^^^^^^^^^^^^^^^
  File "D:\Projects\Python\curse_project\app.py", line 19, in not_found_error
    logging.ERROR("Запрошена несуществующая страница - 404")
TypeError: 'int' object is not callable

During handling of the above exception, another exception occurred:

Traceback (most recent call last):
  File "D:\Projects\Python\curse_project\.venv\Lib\site-packages\werkzeug\serving.py", line 370, in run_wsgi
    execute(self.server.app)
  File "D:\Projects\Python\curse_project\.venv\Lib\site-packages\werkzeug\serving.py", line 331, in execute
    application_iter = app(environ, start_response)
                       ^^^^^^^^^^^^^^^^^^^^^^^^^^^^
  File "D:\Projects\Python\curse_project\.venv\Lib\site-packages\flask\app.py", line 1536, in __call__
    return self.wsgi_app(environ, start_response)
           ^^^^^^^^^^^^^^^^^^^^^^^^^^^^^^^^^^^^^^
  File "D:\Projects\Python\curse_project\.venv\Lib\site-packages\flask\app.py", line 1514, in wsgi_app
    response = self.handle_exception(e)
               ^^^^^^^^^^^^^^^^^^^^^^^^
  File "D:\Projects\Python\curse_project\.venv\Lib\site-packages\flask\app.py", line 860, in handle_exception
    server_error = self.ensure_sync(handler)(server_error)
                   ^^^^^^^^^^^^^^^^^^^^^^^^^^^^^^^^^^^^^^^
  File "D:\Projects\Python\curse_project\app.py", line 24, in server_international_error
    logging.ERROR("Ошибка на стороне сервера - 500")
TypeError: 'int' object is not callable
2025-07-29 20:14:07,317 [INFO] 127.0.0.1 - - [29/Jul/2025 20:14:07] "[36mGET /static/img/eye.png HTTP/1.1[0m" 304 -
2025-07-29 20:14:10,903 [INFO] 127.0.0.1 - - [29/Jul/2025 20:14:10] "GET /posts/1 HTTP/1.1" 200 -
2025-07-29 20:14:10,956 [INFO] 127.0.0.1 - - [29/Jul/2025 20:14:10] "[36mGET /static/css/styles.min.css HTTP/1.1[0m" 304 -
2025-07-29 20:14:10,958 [ERROR] Exception on /posts/img/bookmark.png [GET]
Traceback (most recent call last):
  File "D:\Projects\Python\curse_project\.venv\Lib\site-packages\flask\app.py", line 917, in full_dispatch_request
    rv = self.dispatch_request()
         ^^^^^^^^^^^^^^^^^^^^^^^
  File "D:\Projects\Python\curse_project\.venv\Lib\site-packages\flask\app.py", line 891, in dispatch_request
    self.raise_routing_exception(req)
  File "D:\Projects\Python\curse_project\.venv\Lib\site-packages\flask\app.py", line 500, in raise_routing_exception
    raise request.routing_exception  # type: ignore[misc]
    ^^^^^^^^^^^^^^^^^^^^^^^^^^^^^^^
  File "D:\Projects\Python\curse_project\.venv\Lib\site-packages\flask\ctx.py", line 362, in match_request
    result = self.url_adapter.match(return_rule=True)  # type: ignore
             ^^^^^^^^^^^^^^^^^^^^^^^^^^^^^^^^^^^^^^^^
  File "D:\Projects\Python\curse_project\.venv\Lib\site-packages\werkzeug\routing\map.py", line 629, in match
    raise NotFound() from None
werkzeug.exceptions.NotFound: 404 Not Found: The requested URL was not found on the server. If you entered the URL manually please check your spelling and try again.

During handling of the above exception, another exception occurred:

Traceback (most recent call last):
  File "D:\Projects\Python\curse_project\.venv\Lib\site-packages\flask\app.py", line 1511, in wsgi_app
    response = self.full_dispatch_request()
               ^^^^^^^^^^^^^^^^^^^^^^^^^^^^
  File "D:\Projects\Python\curse_project\.venv\Lib\site-packages\flask\app.py", line 919, in full_dispatch_request
    rv = self.handle_user_exception(e)
         ^^^^^^^^^^^^^^^^^^^^^^^^^^^^^
  File "D:\Projects\Python\curse_project\.venv\Lib\site-packages\flask\app.py", line 802, in handle_user_exception
    return self.handle_http_exception(e)
           ^^^^^^^^^^^^^^^^^^^^^^^^^^^^^
  File "D:\Projects\Python\curse_project\.venv\Lib\site-packages\flask\app.py", line 777, in handle_http_exception
    return self.ensure_sync(handler)(e)  # type: ignore[no-any-return]
           ^^^^^^^^^^^^^^^^^^^^^^^^^^^^
  File "D:\Projects\Python\curse_project\app.py", line 19, in not_found_error
    logging.ERROR("Запрошена несуществующая страница - 404")
TypeError: 'int' object is not callable
2025-07-29 20:14:10,964 [INFO] 127.0.0.1 - - [29/Jul/2025 20:14:10] "[36mGET /static/img/eye.png HTTP/1.1[0m" 304 -
2025-07-29 20:14:10,966 [INFO] 127.0.0.1 - - [29/Jul/2025 20:14:10] "[35m[1mGET /posts/img/bookmark.png HTTP/1.1[0m" 500 -
2025-07-29 20:14:10,975 [ERROR] Error on request:
Traceback (most recent call last):
  File "D:\Projects\Python\curse_project\.venv\Lib\site-packages\flask\app.py", line 917, in full_dispatch_request
    rv = self.dispatch_request()
         ^^^^^^^^^^^^^^^^^^^^^^^
  File "D:\Projects\Python\curse_project\.venv\Lib\site-packages\flask\app.py", line 891, in dispatch_request
    self.raise_routing_exception(req)
  File "D:\Projects\Python\curse_project\.venv\Lib\site-packages\flask\app.py", line 500, in raise_routing_exception
    raise request.routing_exception  # type: ignore[misc]
  File "D:\Projects\Python\curse_project\.venv\Lib\site-packages\flask\ctx.py", line 362, in match_request
    result = self.url_adapter.match(return_rule=True)  # type: ignore
             ^^^^^^^^^^^^^^^^^^^^^^^^^^^^^^^^^^^^^^^^^^^^^^^^^^^^^^^^
  File "D:\Projects\Python\curse_project\.venv\Lib\site-packages\werkzeug\routing\map.py", line 629, in match
    raise NotFound() from None
werkzeug.exceptions.NotFound: 404 Not Found: The requested URL was not found on the server. If you entered the URL manually please check your spelling and try again.

During handling of the above exception, another exception occurred:

Traceback (most recent call last):
  File "D:\Projects\Python\curse_project\.venv\Lib\site-packages\flask\app.py", line 1511, in wsgi_app
    response = self.full_dispatch_request()
               ^^^^^^^^^^^^^^^^^^^^^^^^^^^^
  File "D:\Projects\Python\curse_project\.venv\Lib\site-packages\flask\app.py", line 919, in full_dispatch_request
    rv = self.handle_user_exception(e)
         ^^^^^^^^^^^^^^^^^^^^^^^^^^^^^
  File "D:\Projects\Python\curse_project\.venv\Lib\site-packages\flask\app.py", line 802, in handle_user_exception
    return self.handle_http_exception(e)
           ^^^^^^^^^^^^^^^^^^^^^^^^^^^^^
  File "D:\Projects\Python\curse_project\.venv\Lib\site-packages\flask\app.py", line 777, in handle_http_exception
    return self.ensure_sync(handler)(e)  # type: ignore[no-any-return]
           ^^^^^^^^^^^^^^^^^^^^^^^^^^^^^^^^^^^^^^^^^^^^^^^^^^^^^^^^^^^
  File "D:\Projects\Python\curse_project\app.py", line 19, in not_found_error
    logging.ERROR("Запрошена несуществующая страница - 404")
TypeError: 'int' object is not callable

During handling of the above exception, another exception occurred:

Traceback (most recent call last):
  File "D:\Projects\Python\curse_project\.venv\Lib\site-packages\werkzeug\serving.py", line 370, in run_wsgi
    execute(self.server.app)
  File "D:\Projects\Python\curse_project\.venv\Lib\site-packages\werkzeug\serving.py", line 331, in execute
    application_iter = app(environ, start_response)
                       ^^^^^^^^^^^^^^^^^^^^^^^^^^^^
  File "D:\Projects\Python\curse_project\.venv\Lib\site-packages\flask\app.py", line 1536, in __call__
    return self.wsgi_app(environ, start_response)
           ^^^^^^^^^^^^^^^^^^^^^^^^^^^^^^^^^^^^^^
  File "D:\Projects\Python\curse_project\.venv\Lib\site-packages\flask\app.py", line 1514, in wsgi_app
    response = self.handle_exception(e)
               ^^^^^^^^^^^^^^^^^^^^^^^^
  File "D:\Projects\Python\curse_project\.venv\Lib\site-packages\flask\app.py", line 860, in handle_exception
    server_error = self.ensure_sync(handler)(server_error)
                   ^^^^^^^^^^^^^^^^^^^^^^^^^^^^^^^^^^^^^^^
  File "D:\Projects\Python\curse_project\app.py", line 24, in server_international_error
    logging.ERROR("Ошибка на стороне сервера - 500")
TypeError: 'int' object is not callable
2025-07-29 20:14:10,998 [ERROR] Exception on /favicon.ico [GET]
Traceback (most recent call last):
  File "D:\Projects\Python\curse_project\.venv\Lib\site-packages\flask\app.py", line 917, in full_dispatch_request
    rv = self.dispatch_request()
         ^^^^^^^^^^^^^^^^^^^^^^^
  File "D:\Projects\Python\curse_project\.venv\Lib\site-packages\flask\app.py", line 891, in dispatch_request
    self.raise_routing_exception(req)
  File "D:\Projects\Python\curse_project\.venv\Lib\site-packages\flask\app.py", line 500, in raise_routing_exception
    raise request.routing_exception  # type: ignore[misc]
    ^^^^^^^^^^^^^^^^^^^^^^^^^^^^^^^
  File "D:\Projects\Python\curse_project\.venv\Lib\site-packages\flask\ctx.py", line 362, in match_request
    result = self.url_adapter.match(return_rule=True)  # type: ignore
             ^^^^^^^^^^^^^^^^^^^^^^^^^^^^^^^^^^^^^^^^
  File "D:\Projects\Python\curse_project\.venv\Lib\site-packages\werkzeug\routing\map.py", line 629, in match
    raise NotFound() from None
werkzeug.exceptions.NotFound: 404 Not Found: The requested URL was not found on the server. If you entered the URL manually please check your spelling and try again.

During handling of the above exception, another exception occurred:

Traceback (most recent call last):
  File "D:\Projects\Python\curse_project\.venv\Lib\site-packages\flask\app.py", line 1511, in wsgi_app
    response = self.full_dispatch_request()
               ^^^^^^^^^^^^^^^^^^^^^^^^^^^^
  File "D:\Projects\Python\curse_project\.venv\Lib\site-packages\flask\app.py", line 919, in full_dispatch_request
    rv = self.handle_user_exception(e)
         ^^^^^^^^^^^^^^^^^^^^^^^^^^^^^
  File "D:\Projects\Python\curse_project\.venv\Lib\site-packages\flask\app.py", line 802, in handle_user_exception
    return self.handle_http_exception(e)
           ^^^^^^^^^^^^^^^^^^^^^^^^^^^^^
  File "D:\Projects\Python\curse_project\.venv\Lib\site-packages\flask\app.py", line 777, in handle_http_exception
    return self.ensure_sync(handler)(e)  # type: ignore[no-any-return]
           ^^^^^^^^^^^^^^^^^^^^^^^^^^^^
  File "D:\Projects\Python\curse_project\app.py", line 19, in not_found_error
    logging.ERROR("Запрошена несуществующая страница - 404")
TypeError: 'int' object is not callable
2025-07-29 20:14:11,001 [INFO] 127.0.0.1 - - [29/Jul/2025 20:14:11] "[35m[1mGET /favicon.ico HTTP/1.1[0m" 500 -
2025-07-29 20:14:11,008 [ERROR] Error on request:
Traceback (most recent call last):
  File "D:\Projects\Python\curse_project\.venv\Lib\site-packages\flask\app.py", line 917, in full_dispatch_request
    rv = self.dispatch_request()
         ^^^^^^^^^^^^^^^^^^^^^^^
  File "D:\Projects\Python\curse_project\.venv\Lib\site-packages\flask\app.py", line 891, in dispatch_request
    self.raise_routing_exception(req)
  File "D:\Projects\Python\curse_project\.venv\Lib\site-packages\flask\app.py", line 500, in raise_routing_exception
    raise request.routing_exception  # type: ignore[misc]
  File "D:\Projects\Python\curse_project\.venv\Lib\site-packages\flask\ctx.py", line 362, in match_request
    result = self.url_adapter.match(return_rule=True)  # type: ignore
             ^^^^^^^^^^^^^^^^^^^^^^^^^^^^^^^^^^^^^^^^^^^^^^^^^^^^^^^^
  File "D:\Projects\Python\curse_project\.venv\Lib\site-packages\werkzeug\routing\map.py", line 629, in match
    raise NotFound() from None
werkzeug.exceptions.NotFound: 404 Not Found: The requested URL was not found on the server. If you entered the URL manually please check your spelling and try again.

During handling of the above exception, another exception occurred:

Traceback (most recent call last):
  File "D:\Projects\Python\curse_project\.venv\Lib\site-packages\flask\app.py", line 1511, in wsgi_app
    response = self.full_dispatch_request()
               ^^^^^^^^^^^^^^^^^^^^^^^^^^^^
  File "D:\Projects\Python\curse_project\.venv\Lib\site-packages\flask\app.py", line 919, in full_dispatch_request
    rv = self.handle_user_exception(e)
         ^^^^^^^^^^^^^^^^^^^^^^^^^^^^^
  File "D:\Projects\Python\curse_project\.venv\Lib\site-packages\flask\app.py", line 802, in handle_user_exception
    return self.handle_http_exception(e)
           ^^^^^^^^^^^^^^^^^^^^^^^^^^^^^
  File "D:\Projects\Python\curse_project\.venv\Lib\site-packages\flask\app.py", line 777, in handle_http_exception
    return self.ensure_sync(handler)(e)  # type: ignore[no-any-return]
           ^^^^^^^^^^^^^^^^^^^^^^^^^^^^^^^^^^^^^^^^^^^^^^^^^^^^^^^^^^^
  File "D:\Projects\Python\curse_project\app.py", line 19, in not_found_error
    logging.ERROR("Запрошена несуществующая страница - 404")
TypeError: 'int' object is not callable

During handling of the above exception, another exception occurred:

Traceback (most recent call last):
  File "D:\Projects\Python\curse_project\.venv\Lib\site-packages\werkzeug\serving.py", line 370, in run_wsgi
    execute(self.server.app)
  File "D:\Projects\Python\curse_project\.venv\Lib\site-packages\werkzeug\serving.py", line 331, in execute
    application_iter = app(environ, start_response)
                       ^^^^^^^^^^^^^^^^^^^^^^^^^^^^
  File "D:\Projects\Python\curse_project\.venv\Lib\site-packages\flask\app.py", line 1536, in __call__
    return self.wsgi_app(environ, start_response)
           ^^^^^^^^^^^^^^^^^^^^^^^^^^^^^^^^^^^^^^
  File "D:\Projects\Python\curse_project\.venv\Lib\site-packages\flask\app.py", line 1514, in wsgi_app
    response = self.handle_exception(e)
               ^^^^^^^^^^^^^^^^^^^^^^^^
  File "D:\Projects\Python\curse_project\.venv\Lib\site-packages\flask\app.py", line 860, in handle_exception
    server_error = self.ensure_sync(handler)(server_error)
                   ^^^^^^^^^^^^^^^^^^^^^^^^^^^^^^^^^^^^^^^
  File "D:\Projects\Python\curse_project\app.py", line 24, in server_international_error
    logging.ERROR("Ошибка на стороне сервера - 500")
TypeError: 'int' object is not callable
2025-07-29 20:14:20,519 [INFO] 127.0.0.1 - - [29/Jul/2025 20:14:20] "GET /api/posts HTTP/1.1" 200 -
2025-07-29 20:14:20,609 [ERROR] Exception on /favicon.ico [GET]
Traceback (most recent call last):
  File "D:\Projects\Python\curse_project\.venv\Lib\site-packages\flask\app.py", line 917, in full_dispatch_request
    rv = self.dispatch_request()
         ^^^^^^^^^^^^^^^^^^^^^^^
  File "D:\Projects\Python\curse_project\.venv\Lib\site-packages\flask\app.py", line 891, in dispatch_request
    self.raise_routing_exception(req)
  File "D:\Projects\Python\curse_project\.venv\Lib\site-packages\flask\app.py", line 500, in raise_routing_exception
    raise request.routing_exception  # type: ignore[misc]
    ^^^^^^^^^^^^^^^^^^^^^^^^^^^^^^^
  File "D:\Projects\Python\curse_project\.venv\Lib\site-packages\flask\ctx.py", line 362, in match_request
    result = self.url_adapter.match(return_rule=True)  # type: ignore
             ^^^^^^^^^^^^^^^^^^^^^^^^^^^^^^^^^^^^^^^^
  File "D:\Projects\Python\curse_project\.venv\Lib\site-packages\werkzeug\routing\map.py", line 629, in match
    raise NotFound() from None
werkzeug.exceptions.NotFound: 404 Not Found: The requested URL was not found on the server. If you entered the URL manually please check your spelling and try again.

During handling of the above exception, another exception occurred:

Traceback (most recent call last):
  File "D:\Projects\Python\curse_project\.venv\Lib\site-packages\flask\app.py", line 1511, in wsgi_app
    response = self.full_dispatch_request()
               ^^^^^^^^^^^^^^^^^^^^^^^^^^^^
  File "D:\Projects\Python\curse_project\.venv\Lib\site-packages\flask\app.py", line 919, in full_dispatch_request
    rv = self.handle_user_exception(e)
         ^^^^^^^^^^^^^^^^^^^^^^^^^^^^^
  File "D:\Projects\Python\curse_project\.venv\Lib\site-packages\flask\app.py", line 802, in handle_user_exception
    return self.handle_http_exception(e)
           ^^^^^^^^^^^^^^^^^^^^^^^^^^^^^
  File "D:\Projects\Python\curse_project\.venv\Lib\site-packages\flask\app.py", line 777, in handle_http_exception
    return self.ensure_sync(handler)(e)  # type: ignore[no-any-return]
           ^^^^^^^^^^^^^^^^^^^^^^^^^^^^
  File "D:\Projects\Python\curse_project\app.py", line 19, in not_found_error
    logging.ERROR("Запрошена несуществующая страница - 404")
TypeError: 'int' object is not callable
2025-07-29 20:14:20,612 [INFO] 127.0.0.1 - - [29/Jul/2025 20:14:20] "[35m[1mGET /favicon.ico HTTP/1.1[0m" 500 -
2025-07-29 20:14:20,619 [ERROR] Error on request:
Traceback (most recent call last):
  File "D:\Projects\Python\curse_project\.venv\Lib\site-packages\flask\app.py", line 917, in full_dispatch_request
    rv = self.dispatch_request()
         ^^^^^^^^^^^^^^^^^^^^^^^
  File "D:\Projects\Python\curse_project\.venv\Lib\site-packages\flask\app.py", line 891, in dispatch_request
    self.raise_routing_exception(req)
  File "D:\Projects\Python\curse_project\.venv\Lib\site-packages\flask\app.py", line 500, in raise_routing_exception
    raise request.routing_exception  # type: ignore[misc]
  File "D:\Projects\Python\curse_project\.venv\Lib\site-packages\flask\ctx.py", line 362, in match_request
    result = self.url_adapter.match(return_rule=True)  # type: ignore
             ^^^^^^^^^^^^^^^^^^^^^^^^^^^^^^^^^^^^^^^^^^^^^^^^^^^^^^^^
  File "D:\Projects\Python\curse_project\.venv\Lib\site-packages\werkzeug\routing\map.py", line 629, in match
    raise NotFound() from None
werkzeug.exceptions.NotFound: 404 Not Found: The requested URL was not found on the server. If you entered the URL manually please check your spelling and try again.

During handling of the above exception, another exception occurred:

Traceback (most recent call last):
  File "D:\Projects\Python\curse_project\.venv\Lib\site-packages\flask\app.py", line 1511, in wsgi_app
    response = self.full_dispatch_request()
               ^^^^^^^^^^^^^^^^^^^^^^^^^^^^
  File "D:\Projects\Python\curse_project\.venv\Lib\site-packages\flask\app.py", line 919, in full_dispatch_request
    rv = self.handle_user_exception(e)
         ^^^^^^^^^^^^^^^^^^^^^^^^^^^^^
  File "D:\Projects\Python\curse_project\.venv\Lib\site-packages\flask\app.py", line 802, in handle_user_exception
    return self.handle_http_exception(e)
           ^^^^^^^^^^^^^^^^^^^^^^^^^^^^^
  File "D:\Projects\Python\curse_project\.venv\Lib\site-packages\flask\app.py", line 777, in handle_http_exception
    return self.ensure_sync(handler)(e)  # type: ignore[no-any-return]
           ^^^^^^^^^^^^^^^^^^^^^^^^^^^^^^^^^^^^^^^^^^^^^^^^^^^^^^^^^^^
  File "D:\Projects\Python\curse_project\app.py", line 19, in not_found_error
    logging.ERROR("Запрошена несуществующая страница - 404")
TypeError: 'int' object is not callable

During handling of the above exception, another exception occurred:

Traceback (most recent call last):
  File "D:\Projects\Python\curse_project\.venv\Lib\site-packages\werkzeug\serving.py", line 370, in run_wsgi
    execute(self.server.app)
  File "D:\Projects\Python\curse_project\.venv\Lib\site-packages\werkzeug\serving.py", line 331, in execute
    application_iter = app(environ, start_response)
                       ^^^^^^^^^^^^^^^^^^^^^^^^^^^^
  File "D:\Projects\Python\curse_project\.venv\Lib\site-packages\flask\app.py", line 1536, in __call__
    return self.wsgi_app(environ, start_response)
           ^^^^^^^^^^^^^^^^^^^^^^^^^^^^^^^^^^^^^^
  File "D:\Projects\Python\curse_project\.venv\Lib\site-packages\flask\app.py", line 1514, in wsgi_app
    response = self.handle_exception(e)
               ^^^^^^^^^^^^^^^^^^^^^^^^
  File "D:\Projects\Python\curse_project\.venv\Lib\site-packages\flask\app.py", line 860, in handle_exception
    server_error = self.ensure_sync(handler)(server_error)
                   ^^^^^^^^^^^^^^^^^^^^^^^^^^^^^^^^^^^^^^^
  File "D:\Projects\Python\curse_project\app.py", line 24, in server_international_error
    logging.ERROR("Ошибка на стороне сервера - 500")
TypeError: 'int' object is not callable
2025-07-29 20:14:26,196 [INFO] 127.0.0.1 - - [29/Jul/2025 20:14:26] "GET /api/posts/1 HTTP/1.1" 200 -
2025-07-29 20:14:26,264 [ERROR] Exception on /favicon.ico [GET]
Traceback (most recent call last):
  File "D:\Projects\Python\curse_project\.venv\Lib\site-packages\flask\app.py", line 917, in full_dispatch_request
    rv = self.dispatch_request()
         ^^^^^^^^^^^^^^^^^^^^^^^
  File "D:\Projects\Python\curse_project\.venv\Lib\site-packages\flask\app.py", line 891, in dispatch_request
    self.raise_routing_exception(req)
  File "D:\Projects\Python\curse_project\.venv\Lib\site-packages\flask\app.py", line 500, in raise_routing_exception
    raise request.routing_exception  # type: ignore[misc]
    ^^^^^^^^^^^^^^^^^^^^^^^^^^^^^^^
  File "D:\Projects\Python\curse_project\.venv\Lib\site-packages\flask\ctx.py", line 362, in match_request
    result = self.url_adapter.match(return_rule=True)  # type: ignore
             ^^^^^^^^^^^^^^^^^^^^^^^^^^^^^^^^^^^^^^^^
  File "D:\Projects\Python\curse_project\.venv\Lib\site-packages\werkzeug\routing\map.py", line 629, in match
    raise NotFound() from None
werkzeug.exceptions.NotFound: 404 Not Found: The requested URL was not found on the server. If you entered the URL manually please check your spelling and try again.

During handling of the above exception, another exception occurred:

Traceback (most recent call last):
  File "D:\Projects\Python\curse_project\.venv\Lib\site-packages\flask\app.py", line 1511, in wsgi_app
    response = self.full_dispatch_request()
               ^^^^^^^^^^^^^^^^^^^^^^^^^^^^
  File "D:\Projects\Python\curse_project\.venv\Lib\site-packages\flask\app.py", line 919, in full_dispatch_request
    rv = self.handle_user_exception(e)
         ^^^^^^^^^^^^^^^^^^^^^^^^^^^^^
  File "D:\Projects\Python\curse_project\.venv\Lib\site-packages\flask\app.py", line 802, in handle_user_exception
    return self.handle_http_exception(e)
           ^^^^^^^^^^^^^^^^^^^^^^^^^^^^^
  File "D:\Projects\Python\curse_project\.venv\Lib\site-packages\flask\app.py", line 777, in handle_http_exception
    return self.ensure_sync(handler)(e)  # type: ignore[no-any-return]
           ^^^^^^^^^^^^^^^^^^^^^^^^^^^^
  File "D:\Projects\Python\curse_project\app.py", line 19, in not_found_error
    logging.ERROR("Запрошена несуществующая страница - 404")
TypeError: 'int' object is not callable
2025-07-29 20:14:26,268 [INFO] 127.0.0.1 - - [29/Jul/2025 20:14:26] "[35m[1mGET /favicon.ico HTTP/1.1[0m" 500 -
2025-07-29 20:14:26,278 [ERROR] Error on request:
Traceback (most recent call last):
  File "D:\Projects\Python\curse_project\.venv\Lib\site-packages\flask\app.py", line 917, in full_dispatch_request
    rv = self.dispatch_request()
         ^^^^^^^^^^^^^^^^^^^^^^^
  File "D:\Projects\Python\curse_project\.venv\Lib\site-packages\flask\app.py", line 891, in dispatch_request
    self.raise_routing_exception(req)
  File "D:\Projects\Python\curse_project\.venv\Lib\site-packages\flask\app.py", line 500, in raise_routing_exception
    raise request.routing_exception  # type: ignore[misc]
  File "D:\Projects\Python\curse_project\.venv\Lib\site-packages\flask\ctx.py", line 362, in match_request
    result = self.url_adapter.match(return_rule=True)  # type: ignore
             ^^^^^^^^^^^^^^^^^^^^^^^^^^^^^^^^^^^^^^^^^^^^^^^^^^^^^^^^
  File "D:\Projects\Python\curse_project\.venv\Lib\site-packages\werkzeug\routing\map.py", line 629, in match
    raise NotFound() from None
werkzeug.exceptions.NotFound: 404 Not Found: The requested URL was not found on the server. If you entered the URL manually please check your spelling and try again.

During handling of the above exception, another exception occurred:

Traceback (most recent call last):
  File "D:\Projects\Python\curse_project\.venv\Lib\site-packages\flask\app.py", line 1511, in wsgi_app
    response = self.full_dispatch_request()
               ^^^^^^^^^^^^^^^^^^^^^^^^^^^^
  File "D:\Projects\Python\curse_project\.venv\Lib\site-packages\flask\app.py", line 919, in full_dispatch_request
    rv = self.handle_user_exception(e)
         ^^^^^^^^^^^^^^^^^^^^^^^^^^^^^
  File "D:\Projects\Python\curse_project\.venv\Lib\site-packages\flask\app.py", line 802, in handle_user_exception
    return self.handle_http_exception(e)
           ^^^^^^^^^^^^^^^^^^^^^^^^^^^^^
  File "D:\Projects\Python\curse_project\.venv\Lib\site-packages\flask\app.py", line 777, in handle_http_exception
    return self.ensure_sync(handler)(e)  # type: ignore[no-any-return]
           ^^^^^^^^^^^^^^^^^^^^^^^^^^^^^^^^^^^^^^^^^^^^^^^^^^^^^^^^^^^
  File "D:\Projects\Python\curse_project\app.py", line 19, in not_found_error
    logging.ERROR("Запрошена несуществующая страница - 404")
TypeError: 'int' object is not callable

During handling of the above exception, another exception occurred:

Traceback (most recent call last):
  File "D:\Projects\Python\curse_project\.venv\Lib\site-packages\werkzeug\serving.py", line 370, in run_wsgi
    execute(self.server.app)
  File "D:\Projects\Python\curse_project\.venv\Lib\site-packages\werkzeug\serving.py", line 331, in execute
    application_iter = app(environ, start_response)
                       ^^^^^^^^^^^^^^^^^^^^^^^^^^^^
  File "D:\Projects\Python\curse_project\.venv\Lib\site-packages\flask\app.py", line 1536, in __call__
    return self.wsgi_app(environ, start_response)
           ^^^^^^^^^^^^^^^^^^^^^^^^^^^^^^^^^^^^^^
  File "D:\Projects\Python\curse_project\.venv\Lib\site-packages\flask\app.py", line 1514, in wsgi_app
    response = self.handle_exception(e)
               ^^^^^^^^^^^^^^^^^^^^^^^^
  File "D:\Projects\Python\curse_project\.venv\Lib\site-packages\flask\app.py", line 860, in handle_exception
    server_error = self.ensure_sync(handler)(server_error)
                   ^^^^^^^^^^^^^^^^^^^^^^^^^^^^^^^^^^^^^^^
  File "D:\Projects\Python\curse_project\app.py", line 24, in server_international_error
    logging.ERROR("Ошибка на стороне сервера - 500")
TypeError: 'int' object is not callable
2025-07-29 20:16:13,552 [INFO] [31m[1mWARNING: This is a development server. Do not use it in a production deployment. Use a production WSGI server instead.[0m
 * Running on http://127.0.0.1:5000
2025-07-29 20:16:13,552 [INFO] [33mPress CTRL+C to quit[0m
